Running tests under Python 3.9.18: /home/jmw/anaconda3/envs/vct_tf/bin/python
[ RUN      ] ModelsTest.test_session
[  SKIPPED ] ModelsTest.test_session
[ RUN      ] ModelsTest.test_train_eval
INFO:tensorflow:time(__main__.ModelsTest.test_train_eval): 0.91s
I1121 16:06:11.209519 140583571796352 test_util.py:2460] time(__main__.ModelsTest.test_train_eval): 0.91s
[  FAILED  ] ModelsTest.test_train_eval
======================================================================
ERROR: test_train_eval (__main__.ModelsTest)
ModelsTest.test_train_eval
----------------------------------------------------------------------
Traceback (most recent call last):
  File "/home/jmw/ing/myfi/vfi/src/models_test.py", line 86, in test_train_eval
    ckpt_p = model.write_ckpt(args.write_ckpt_dir, step=epoch)
UnboundLocalError: local variable 'epoch' referenced before assignment
----------------------------------------------------------------------
Ran 2 tests in 0.914s
FAILED (errors=1, skipped=1)
resume /home/jmw/ing/myfi/vfi/ckpt