Running tests under Python 3.9.18: /home/jmw/anaconda3/envs/vct_tf/bin/python
[ RUN      ] ModelsTest.test_session
[  SKIPPED ] ModelsTest.test_session
[ RUN      ] ModelsTest.test_train_eval
  0%|                                                                                                                                                 | 0/12829 [00:13<?, ?batch/s]
INFO:tensorflow:time(__main__.ModelsTest.test_train_eval): 13.97s
I1121 13:22:55.266959 140062122705280 test_util.py:2460] time(__main__.ModelsTest.test_train_eval): 13.97s
[  FAILED  ] ModelsTest.test_train_eval
======================================================================
ERROR: test_train_eval (__main__.ModelsTest)
ModelsTest.test_train_eval
----------------------------------------------------------------------
Traceback (most recent call last):
  File "/home/jmw/ing/myfi/vfi/src/models_test.py", line 92, in test_train_eval
    tepoch.set_postfix(epoch=epoch,psnr=metrics.scalars['psnr'].numpy() , loss =metrics.scalars['loss'].numpy() ,mse =metrics.scalars['mse'].numpy()  )
AttributeError: 'dict' object has no attribute 'scalars'
----------------------------------------------------------------------
Ran 2 tests in 14.080s
FAILED (errors=1, skipped=1)