Running tests under Python 3.9.18: /home/jmw/anaconda3/envs/vct_tf/bin/python
[ RUN      ] ModelsTest.test_session
[  SKIPPED ] ModelsTest.test_session
[ RUN      ] ModelsTest.test_train_eval
  0%|                                                                                                                                           | 0/802 [00:04<?, ?batch/s]
INFO:tensorflow:time(__main__.ModelsTest.test_train_eval): 5.41s
I1121 13:39:00.380784 139624319660416 test_util.py:2460] time(__main__.ModelsTest.test_train_eval): 5.41s
[  FAILED  ] ModelsTest.test_train_eval
======================================================================
ERROR: test_train_eval (__main__.ModelsTest)
ModelsTest.test_train_eval
----------------------------------------------------------------------
Traceback (most recent call last):
  File "/home/jmw/ing/myfi/vfi/src/models_test.py", line 91, in test_train_eval
    metrics=train_step(img0,gt,img1)
  File "/home/jmw/anaconda3/envs/vct_tf/lib/python3.9/site-packages/tensorflow/python/util/traceback_utils.py", line 141, in error_handler
    return fn(*args, **kwargs)
  File "/home/jmw/anaconda3/envs/vct_tf/lib/python3.9/site-packages/tensorflow/python/eager/def_function.py", line 915, in __call__
    result = self._call(*args, **kwds)
  File "/home/jmw/anaconda3/envs/vct_tf/lib/python3.9/site-packages/tensorflow/python/eager/def_function.py", line 963, in _call
    self._initialize(args, kwds, add_initializers_to=initializers)
  File "/home/jmw/anaconda3/envs/vct_tf/lib/python3.9/site-packages/tensorflow/python/eager/def_function.py", line 785, in _initialize
    self._stateful_fn._get_concrete_function_internal_garbage_collected(  # pylint: disable=protected-access
  File "/home/jmw/anaconda3/envs/vct_tf/lib/python3.9/site-packages/tensorflow/python/eager/function.py", line 2523, in _get_concrete_function_internal_garbage_collected
    graph_function, _ = self._maybe_define_function(args, kwargs)
  File "/home/jmw/anaconda3/envs/vct_tf/lib/python3.9/site-packages/tensorflow/python/eager/function.py", line 2760, in _maybe_define_function
    graph_function = self._create_graph_function(args, kwargs)
  File "/home/jmw/anaconda3/envs/vct_tf/lib/python3.9/site-packages/tensorflow/python/eager/function.py", line 2670, in _create_graph_function
    func_graph_module.func_graph_from_py_func(
  File "/home/jmw/anaconda3/envs/vct_tf/lib/python3.9/site-packages/tensorflow/python/framework/func_graph.py", line 1247, in func_graph_from_py_func
    func_outputs = python_func(*func_args, **func_kwargs)
  File "/home/jmw/anaconda3/envs/vct_tf/lib/python3.9/site-packages/tensorflow/python/eager/def_function.py", line 677, in wrapped_fn
    out = weak_wrapped_fn().__wrapped__(*args, **kwds)
  File "/home/jmw/anaconda3/envs/vct_tf/lib/python3.9/site-packages/tensorflow/python/framework/func_graph.py", line 1233, in autograph_handler
    raise e.ag_error_metadata.to_exception(e)
  File "/home/jmw/anaconda3/envs/vct_tf/lib/python3.9/site-packages/tensorflow/python/framework/func_graph.py", line 1222, in autograph_handler
    return autograph.converted_call(
  File "/home/jmw/anaconda3/envs/vct_tf/lib/python3.9/site-packages/tensorflow/python/autograph/impl/api.py", line 439, in converted_call
    result = converted_f(*effective_args, **kwargs)
  File "/tmp/__autograph_generated_filermuisiww.py", line 12, in tf__train_step
    (pred, metric) = ag__.converted_call(ag__.ld(self).interpolator, (ag__.ld(img0), ag__.ld(gt), ag__.ld(img1)), None, fscope)
  File "/home/jmw/anaconda3/envs/vct_tf/lib/python3.9/site-packages/tensorflow/python/autograph/impl/api.py", line 441, in converted_call
    result = converted_f(*effective_args)
  File "/tmp/__autograph_generated_file6hm3z_0u.py", line 85, in tf__interpolator
    ag__.for_stmt(ag__.ld(merged), None, loop_body_1, get_state_2, set_state_2, ('loss_l1',), {'iterate_names': 'merge'})
  File "/home/jmw/anaconda3/envs/vct_tf/lib/python3.9/site-packages/tensorflow/python/autograph/operators/control_flow.py", line 463, in for_stmt
    _py_for_stmt(iter_, extra_test, body, None, None)
  File "/home/jmw/anaconda3/envs/vct_tf/lib/python3.9/site-packages/tensorflow/python/autograph/operators/control_flow.py", line 512, in _py_for_stmt
    body(target)
  File "/home/jmw/anaconda3/envs/vct_tf/lib/python3.9/site-packages/tensorflow/python/autograph/operators/control_flow.py", line 478, in protected_body
    original_body(protected_iter)
  File "/tmp/__autograph_generated_file6hm3z_0u.py", line 83, in loop_body_1
    loss_l1 += ag__.converted_call(tf.reduce_mean, (ag__.converted_call(self.lap, (merge, gt), None, fscope),), None, fscope) * 0.5
AttributeError: in user code:
    File "/home/jmw/ing/myfi/vfi/src/model.py", line 366, in train_step  *
        pred,metric = self.interpolator(img0,gt,img1)
    File "/home/jmw/ing/myfi/vfi/src/model.py", line 433, in interpolator  *
        loss_l1 += tf.reduce_mean(self.lap(merge, gt)) * 0.5
    AttributeError: 'Model' object has no attribute 'lap'
----------------------------------------------------------------------
Ran 2 tests in 5.416s
FAILED (errors=1, skipped=1)