Running tests under Python 3.10.9: /home/lab-com/anaconda3/bin/python3
[ RUN      ] ModelsTest.test_session
[  SKIPPED ] ModelsTest.test_session
[ RUN      ] ModelsTest.test_train_eval
  0%|                                                                                                                                                                                                                 | 0/1604 [00:17<?, ?batch/s]
INFO:tensorflow:time(__main__.ModelsTest.test_train_eval): 17.09s
I0426 19:38:15.256258 139969136775808 test_util.py:2472] time(__main__.ModelsTest.test_train_eval): 17.09s
[  FAILED  ] ModelsTest.test_train_eval
======================================================================
ERROR: test_train_eval (__main__.ModelsTest)
ModelsTest.test_train_eval
----------------------------------------------------------------------
Traceback (most recent call last):
  File "/home/jmw/backup/FILM/vfi/src/train.py", line 92, in test_train_eval
    metrics=train_step(img0,gt,img1)
  File "/home/jmw/.local/lib/python3.10/site-packages/tensorflow/python/util/traceback_utils.py", line 141, in error_handler
    return fn(*args, **kwargs)
  File "/home/jmw/.local/lib/python3.10/site-packages/tensorflow/python/eager/polymorphic_function/polymorphic_function.py", line 831, in __call__
    result = self._call(*args, **kwds)
  File "/home/jmw/.local/lib/python3.10/site-packages/tensorflow/python/eager/polymorphic_function/polymorphic_function.py", line 887, in _call
    self._initialize(args, kwds, add_initializers_to=initializers)
  File "/home/jmw/.local/lib/python3.10/site-packages/tensorflow/python/eager/polymorphic_function/polymorphic_function.py", line 694, in _initialize
    self._concrete_variable_creation_fn = tracing_compilation.trace_function(
  File "/home/jmw/.local/lib/python3.10/site-packages/tensorflow/python/eager/polymorphic_function/tracing_compilation.py", line 178, in trace_function
    concrete_function = _maybe_define_function(
  File "/home/jmw/.local/lib/python3.10/site-packages/tensorflow/python/eager/polymorphic_function/tracing_compilation.py", line 284, in _maybe_define_function
    concrete_function = _create_concrete_function(
  File "/home/jmw/.local/lib/python3.10/site-packages/tensorflow/python/eager/polymorphic_function/tracing_compilation.py", line 308, in _create_concrete_function
    traced_func_graph = func_graph_module.func_graph_from_py_func(
  File "/home/jmw/.local/lib/python3.10/site-packages/tensorflow/python/framework/func_graph.py", line 1059, in func_graph_from_py_func
    func_outputs = python_func(*func_args, **func_kwargs)
  File "/home/jmw/.local/lib/python3.10/site-packages/tensorflow/python/eager/polymorphic_function/polymorphic_function.py", line 597, in wrapped_fn
    out = weak_wrapped_fn().__wrapped__(*args, **kwds)
  File "/home/jmw/.local/lib/python3.10/site-packages/tensorflow/python/eager/polymorphic_function/autograph_util.py", line 52, in autograph_handler
    raise e.ag_error_metadata.to_exception(e)
  File "/home/jmw/.local/lib/python3.10/site-packages/tensorflow/python/eager/polymorphic_function/autograph_util.py", line 41, in autograph_handler
    return api.converted_call(
  File "/home/jmw/.local/lib/python3.10/site-packages/tensorflow/python/autograph/impl/api.py", line 439, in converted_call
    result = converted_f(*effective_args, **kwargs)
  File "/tmp/__autograph_generated_fileji76k0r_.py", line 11, in tf__train_step
    (pred, metric) = ag__.converted_call(ag__.ld(self).interpolator, (ag__.ld(img0), ag__.ld(gt), ag__.ld(img1)), None, fscope)
  File "/home/jmw/.local/lib/python3.10/site-packages/tensorflow/python/autograph/impl/api.py", line 441, in converted_call
    result = converted_f(*effective_args)
TypeError: in user code:
    File "/home/jmw/backup/FILM/vfi/src/models.py", line 86, in train_step  *
        pred,metric = self.interpolator(img0,gt,img1)
    TypeError: outer_factory.<locals>.inner_factory.<locals>.tf__interpolator() missing 1 required positional argument: 'config'
----------------------------------------------------------------------
Ran 2 tests in 17.088s
FAILED (errors=1, skipped=1)