Running tests under Python 3.9.18: /home/jmw/anaconda3/envs/vct_tf/bin/python
[ RUN      ] ModelsTest.test_session
[  SKIPPED ] ModelsTest.test_session
[ RUN      ] ModelsTest.test_train_eval
  0%|                                                                                                          | 0/802 [00:29<?, ?batch/s, epoch=0, loss=0.117, mse=547, psnr=21.5]
INFO:tensorflow:time(__main__.ModelsTest.test_train_eval): 30.83s
I1121 13:23:56.618448 139942720487808 test_util.py:2460] time(__main__.ModelsTest.test_train_eval): 30.83s
[  FAILED  ] ModelsTest.test_train_eval
======================================================================
ERROR: test_train_eval (__main__.ModelsTest)
ModelsTest.test_train_eval
----------------------------------------------------------------------
Traceback (most recent call last):
  File "/home/jmw/ing/myfi/vfi/src/models_test.py", line 93, in test_train_eval
    wandb.log(metrics.scalars)
AttributeError: 'dict' object has no attribute 'scalars'
----------------------------------------------------------------------
Ran 2 tests in 30.948s
FAILED (errors=1, skipped=1)