Running tests under Python 3.9.18: /home/jmw/anaconda3/envs/vct_tf/bin/python
[ RUN      ] ModelsTest.test_session
[  SKIPPED ] ModelsTest.test_session
[ RUN      ] ModelsTest.test_train_eval
INFO:tensorflow:time(__main__.ModelsTest.test_train_eval): 0.91s
I1121 13:13:11.027285 140376178479488 test_util.py:2460] time(__main__.ModelsTest.test_train_eval): 0.91s
[  FAILED  ] ModelsTest.test_train_eval
======================================================================
ERROR: test_train_eval (__main__.ModelsTest)
ModelsTest.test_train_eval
----------------------------------------------------------------------
Traceback (most recent call last):
  File "/home/jmw/ing/myfi/vfi/src/models_test.py", line 85, in test_train_eval
    with tqdm(train_loader , unit ='batch' ) as tepoch :
TypeError: 'module' object is not callable
----------------------------------------------------------------------
Ran 2 tests in 0.912s
FAILED (errors=1, skipped=1)